Workbook

Sheet Backlog
A1: Story ID | B1: Old ID | C1: Epic | D1: Epic name | E1: Story | F1: Requirement | G1: Story points | H1: Sprint | I1: Owner | J1: GitHub username | K1: Status | L1: Branch / evidence
A2: US-01 | B2: US-07 | C2: WBMME-1 | D2: Data Workspace | E2: Upload a CSV dataset | F2: MLE-F-003 | G2: 5 | H2: Sprint 1 | I2: Vikas (Member 4) | J2: vikasvittalaihole | K2: To Do
A3: US-02 | B3: US-08 | C3: WBMME-1 | D3: Data Workspace | E3: Upload validation | F3: MLE-SR-003 | G3: 3 | H3: Sprint 1 | I3: Vikas (Member 4) | J3: vikasvittalaihole | K3: To Do
A4: US-03 | B4: US-09 | C4: WBMME-1 | D4: Data Workspace | E4: Preview and profile a dataset | F4: MLE-F-004 | G4: 3 | H4: Sprint 1 | I4: Vikas (Member 4) | J4: vikasvittalaihole | K4: To Do
A5: US-04 | B5: US-10 | C5: WBMME-1 | D5: Data Workspace | E5: Prepare data | F5: MLE-F-005 | G5: 5 | H5: Sprint 1 | I5: Vikas (Member 4) | J5: vikasvittalaihole | K5: To Do
A6: US-05 | B6: US-11 | C6: WBMME-1 | D6: Data Workspace | E6: Configure train/test split | F6: MLE-F-006 | G6: 3 | H6: Sprint 1 | I6: Vikas (Member 4) | J6: vikasvittalaihole | K6: To Do
A7: US-06 | B7: US-13 | C7: WBMME-2 | D7: Model Training & Selection | E7: Model catalogue | F7: MLE-F-007 | G7: 3 | H7: Sprint 1 | I7: Varnika (Member 2) | J7: varnikasadineni | K7: Done (pending PR review) | L7: feature/us-06-model-catalogue | 23 tests; 1 commit
A8: US-07 | B8: US-14 | C8: WBMME-2 | D8: Model Training & Selection | E8: Set hyperparameters | F8: MLE-F-008 | G8: 5 | H8: Sprint 1 | I8: Varnika (Member 2) | J8: varnikasadineni | K8: Done (pending PR review) | L8: feature/us-07-hyperparameters | 52 tests (cumulative)
A9: US-08 | B9: US-15 | C9: WBMME-2 | D9: Model Training & Selection | E9: Train as a background job | F9: MLE-F-009 | G9: 8 | H9: Sprint 1 | I9: Varnika (Member 2) | J9: varnikasadineni | K9: Done (pending PR review) | L9: feature/us-08-background-training | 95 tests (cumulative)
A10: US-09 | B10: US-16 | C10: WBMME-2 | D10: Model Training & Selection | E10: Safe model artifacts | F10: MLE-SR-004 | G10: 3 | H10: Sprint 1 | I10: Tejas (Member 3) | J10: TejasPonnappa | K10: To Do
A11: US-10 | B11: US-19 | C11: WBMME-3 | D11: Evaluation & Explainability | E11: Evaluation metrics | F11: MLE-F-010 | G11: 5 | H11: Sprint 1 | I11: Tejas (Member 3) | J11: TejasPonnappa | K11: To Do
A12: US-11 | B12: US-26 | C12: WBMME-5 | D12: Testing & Validation | E12: Unit tests for core services | F12: Test Plan 5 | G12: 5 | H12: Sprint 1 | I12: Varnika (Member 2) | J12: varnikasadineni | K12: Done (pending PR review) | L12: feature/us-11-unit-tests | 139 tests (cumulative)
A13: US-12 | B13: US-31 | C13: WBMME-6 | D13: CI/CD, Security & Deployment | E13: CI pipeline | F13: Part-2 Sprint 1 | G13: 5 | H13: Sprint 1 | I13: Soumya (Member 1) | J13: KOTRASAISOUMYASRI | K13: To Do
A14: US-13 | B14: US-35 | C14: WBMME-7 | D14: Final Documentation & Demonstration | E14: Sprint 1 demo video | F14: Part-2 Sprint 1 | G14: 2 | H14: Sprint 1 | I14: Soumya (Member 1) | J14: KOTRASAISOUMYASRI | K14: To Do
A15: US-14 | B15: US-38 | C15: WBMME-8 | D15: Core Platform & Security | E15: Django project skeleton | F15: SAD 3.5, 3.6 | G15: 3 | H15: Sprint 1 | I15: Soumya (Member 1) | J15: KOTRASAISOUMYASRI | K15: To Do
A16: US-15 | B16: US-39 | C16: WBMME-8 | D16: Core Platform & Security | E16: Register and log in | F16: MLE-F-001 | G16: 5 | H16: Sprint 1 | I16: Tejas (Member 3) | J16: TejasPonnappa | K16: To Do
A17: US-16 | B17: US-40 | C17: WBMME-8 | D17: Core Platform & Security | E17: Password hashing | F17: MLE-SR-001 | G17: 2 | H17: Sprint 1 | I17: Soumya (Member 1) | J17: KOTRASAISOUMYASRI | K17: To Do
A18: US-17 | B18: US-41 | C18: WBMME-8 | D18: Core Platform & Security | E18: Role-based access | F18: MLE-F-002 | G18: 5 | H18: Sprint 1 | I18: Tejas (Member 3) | J18: TejasPonnappa | K18: To Do
A19: US-18 | B19: US-42 | C19: WBMME-8 | D19: Core Platform & Security | E19: Sessions and login protection | F19: MLE-SR-007 | G19: 5 | H19: Sprint 1 | I19: Soumya (Member 1) | J19: KOTRASAISOUMYASRI | K19: To Do
A20: US-19 | B20: US-12 | C20: WBMME-1 | D20: Data Workspace | E20: Upload speed target | F20: MLE-NF-001 | G20: 3 | H20: Sprint 2 | I20: Vikas (Member 4) | J20: vikasvittalaihole | K20: To Do
A21: US-20 | B21: US-17 | C21: WBMME-2 | D21: Model Training & Selection | E21: Training speed target | F21: MLE-NF-002 | G21: 3 | H21: Sprint 2 | I21: Varnika (Member 2) | J21: varnikasadineni | K21: Done (pending PR review) | L21: feature/us-20-training-speed | 145 tests incl. 3 perf
A22: US-21 | B22: US-18 | C22: WBMME-2 | D22: Model Training & Selection | E22: Contain failed jobs | F22: MLE-NF-006 | G22: 5 | H22: Sprint 2 | I22: Varnika (Member 2) | J22: varnikasadineni | K22: Done (pending PR review) | L22: feature/us-21-contain-failed-jobs | 158 tests (cumulative)
A23: US-22 | B23: US-20 | C23: WBMME-3 | D23: Evaluation & Explainability | E23: Confusion matrix and metric chart | F23: MLE-F-011 | G23: 5 | H23: Sprint 2 | I23: Tejas (Member 3) | J23: TejasPonnappa | K23: To Do
A24: US-23 | B24: US-21 | C24: WBMME-3 | D24: Evaluation & Explainability | E24: Feature importance | F24: MLE-F-012 | G24: 3 | H24: Sprint 2 | I24: Tejas (Member 3) | J24: TejasPonnappa | K24: To Do
A25: US-24 | B25: US-22 | C25: WBMME-4 | D25: Experiment Management & Reporting | E25: Run history | F25: MLE-F-013 | G25: 5 | H25: Sprint 2 | I25: Vikas (Member 4) | J25: vikasvittalaihole | K25: To Do
A26: US-25 | B26: US-23 | C26: WBMME-4 | D26: Experiment Management & Reporting | E26: Compare runs | F26: MLE-F-014 | G26: 5 | H26: Sprint 2 | I26: Vikas (Member 4) | J26: vikasvittalaihole | K26: To Do
A27: US-26 | B27: US-24 | C27: WBMME-4 | D27: Experiment Management & Reporting | E27: Export results as CSV | F27: MLE-F-015 | G27: 3 | H27: Sprint 2 | I27: Vikas (Member 4) | J27: vikasvittalaihole | K27: To Do
A28: US-27 | B28: US-25 | C28: WBMME-4 | D28: Experiment Management & Reporting | E28: History scale and pagination | F28: MLE-NF-007 | G28: 3 | H28: Sprint 2 | I28: Vikas (Member 4) | J28: vikasvittalaihole | K28: To Do
A29: US-28 | B29: US-27 | C29: WBMME-5 | D29: Testing & Validation | E29: Integration and system tests | F29: Test Plan 13 | G29: 5 | H29: Sprint 2 | I29: Varnika (Member 2) | J29: varnikasadineni | K29: Done (pending PR review) | L29: feature/us-28-integration-system-tests | 202 tests (cumulative)
A30: US-29 | B30: US-28 | C30: WBMME-5 | D30: Testing & Validation | E30: Security validation | F30: MLE-SR-001 to 007 | G30: 5 | H30: Sprint 2 | I30: Soumya (Member 1) | J30: KOTRASAISOUMYASRI | K30: To Do
A31: US-30 | B31: US-29 | C31: WBMME-5 | D31: Testing & Validation | E31: Load test | F31: MLE-NF-003 | G31: 5 | H31: Sprint 2 | I31: Varnika (Member 2) | J31: varnikasadineni | K31: Done (pending PR review) | L31: feature/us-30-load-test | 202 tests; load test passed
A32: US-31 | B32: US-30 | C32: WBMME-5 | D32: Testing & Validation | E32: Usability test | F32: MLE-NF-005 | G32: 3 | H32: Sprint 2 | I32: Tejas (Member 3) | J32: TejasPonnappa | K32: To Do
A33: US-32 | B33: US-32 | C33: WBMME-6 | D33: CI/CD, Security & Deployment | E33: Docker build | F33: MLE-NF-004 | G33: 5 | H33: Sprint 2 | I33: Soumya (Member 1) | J33: KOTRASAISOUMYASRI | K33: To Do
A34: US-33 | B34: US-33 | C34: WBMME-6 | D34: CI/CD, Security & Deployment | E34: HTTPS only | F34: MLE-SR-002 | G34: 3 | H34: Sprint 2 | I34: Soumya (Member 1) | J34: KOTRASAISOUMYASRI | K34: To Do
A35: US-34 | B35: US-34 | C35: WBMME-6 | D35: CI/CD, Security & Deployment | E35: Security scan | F35: Test Plan 5.1 | G35: 3 | H35: Sprint 2 | I35: Soumya (Member 1) | J35: KOTRASAISOUMYASRI | K35: To Do
A36: US-35 | B36: US-36 | C36: WBMME-7 | D36: Final Documentation & Demonstration | E36: Sprint 2 demo video | F36: Part-2 Sprint 2 | G36: 2 | H36: Sprint 2 | I36: Soumya (Member 1) | J36: KOTRASAISOUMYASRI | K36: To Do
A37: US-36 | B37: US-37 | C37: WBMME-7 | D37: Final Documentation & Demonstration | E37: Final report and deviation log | F37: Part-2 Sprint 2 | G37: 3 | H37: Sprint 2 | I37: Soumya (Member 1) | J37: KOTRASAISOUMYASRI | K37: To Do
A38: US-37 | B38: US-43 | C38: WBMME-8 | D38: Core Platform & Security | E38: Admin console | F38: MLE-F-016 | G38: 8 | H38: Sprint 2 | I38: Tejas (Member 3) | J38: TejasPonnappa | K38: To Do
A39: US-38 | B39: US-44 | C39: WBMME-8 | D39: Core Platform & Security | E39: Ownership checks and audit log | F39: MLE-SR-005 | G39: 5 | H39: Sprint 2 | I39: Tejas (Member 3) | J39: TejasPonnappa | K39: To Do
A40: US-39 | B40: US-45 | C40: WBMME-8 | D40: Core Platform & Security | E40: Request and job limits | F40: MLE-SR-006 | G40: 5 | H40: Sprint 2 | I40: Varnika (Member 2) | J40: varnikasadineni | K40: Done (pending PR review) | L40: feature/us-39-request-and-job-limits | 191 tests (cumulative)
...

Sheet Epics
A1: Epic | B1: Name | C1: Old number | D1: Stories | E1: Points | F1: Sprint 1 stories | G1: Sprint 2 stories
A2: WBMME-1 | B2: Data Workspace | C2: WBMME-4 | D2: =COUNTIF(Backlog!$C$2:$C$40,A2) | E2: =SUMIF(Backlog!$C$2:$C$40,A2,Backlog!$G$2:$G$40) | F2: =COUNTIFS(Backlog!$C$2:$C$40,A2,Backlog!$H$2:$H$40,"Sprint 1") | G2: =COUNTIFS(Backlog!$C$2:$C$40,A2,Backlog!$H$2:$H$40,"Sprint 2")
A3: WBMME-2 | B3: Model Training & Selection | C3: WBMME-5 | D3: =COUNTIF(Backlog!$C$2:$C$40,A3) | E3: =SUMIF(Backlog!$C$2:$C$40,A3,Backlog!$G$2:$G$40) | F3: =COUNTIFS(Backlog!$C$2:$C$40,A3,Backlog!$H$2:$H$40,"Sprint 1") | G3: =COUNTIFS(Backlog!$C$2:$C$40,A3,Backlog!$H$2:$H$40,"Sprint 2")
A4: WBMME-3 | B4: Evaluation & Explainability | C4: WBMME-6 | D4: =COUNTIF(Backlog!$C$2:$C$40,A4) | E4: =SUMIF(Backlog!$C$2:$C$40,A4,Backlog!$G$2:$G$40) | F4: =COUNTIFS(Backlog!$C$2:$C$40,A4,Backlog!$H$2:$H$40,"Sprint 1") | G4: =COUNTIFS(Backlog!$C$2:$C$40,A4,Backlog!$H$2:$H$40,"Sprint 2")
A5: WBMME-4 | B5: Experiment Management & Reporting | C5: WBMME-7 | D5: =COUNTIF(Backlog!$C$2:$C$40,A5) | E5: =SUMIF(Backlog!$C$2:$C$40,A5,Backlog!$G$2:$G$40) | F5: =COUNTIFS(Backlog!$C$2:$C$40,A5,Backlog!$H$2:$H$40,"Sprint 1") | G5: =COUNTIFS(Backlog!$C$2:$C$40,A5,Backlog!$H$2:$H$40,"Sprint 2")
A6: WBMME-5 | B6: Testing & Validation | C6: WBMME-8 | D6: =COUNTIF(Backlog!$C$2:$C$40,A6) | E6: =SUMIF(Backlog!$C$2:$C$40,A6,Backlog!$G$2:$G$40) | F6: =COUNTIFS(Backlog!$C$2:$C$40,A6,Backlog!$H$2:$H$40,"Sprint 1") | G6: =COUNTIFS(Backlog!$C$2:$C$40,A6,Backlog!$H$2:$H$40,"Sprint 2")
A7: WBMME-6 | B7: CI/CD, Security & Deployment | C7: WBMME-9 | D7: =COUNTIF(Backlog!$C$2:$C$40,A7) | E7: =SUMIF(Backlog!$C$2:$C$40,A7,Backlog!$G$2:$G$40) | F7: =COUNTIFS(Backlog!$C$2:$C$40,A7,Backlog!$H$2:$H$40,"Sprint 1") | G7: =COUNTIFS(Backlog!$C$2:$C$40,A7,Backlog!$H$2:$H$40,"Sprint 2")
A8: WBMME-7 | B8: Final Documentation & Demonstration | C8: WBMME-10 | D8: =COUNTIF(Backlog!$C$2:$C$40,A8) | E8: =SUMIF(Backlog!$C$2:$C$40,A8,Backlog!$G$2:$G$40) | F8: =COUNTIFS(Backlog!$C$2:$C$40,A8,Backlog!$H$2:$H$40,"Sprint 1") | G8: =COUNTIFS(Backlog!$C$2:$C$40,A8,Backlog!$H$2:$H$40,"Sprint 2")
A9: WBMME-8 | B9: Core Platform & Security | C9: WBMME-11 | D9: =COUNTIF(Backlog!$C$2:$C$40,A9) | E9: =SUMIF(Backlog!$C$2:$C$40,A9,Backlog!$G$2:$G$40) | F9: =COUNTIFS(Backlog!$C$2:$C$40,A9,Backlog!$H$2:$H$40,"Sprint 1") | G9: =COUNTIFS(Backlog!$C$2:$C$40,A9,Backlog!$H$2:$H$40,"Sprint 2")
A10: Total | D10: =SUM(D2:D9) | E10: =SUM(E2:E9) | F10: =SUM(F2:F9) | G10: =SUM(G2:G9)

Sheet Sprint summary
A1: Member | B1: Sprint 1 stories | C1: Sprint 1 points | D1: Sprint 2 stories | E1: Sprint 2 points | F1: Total stories | G1: Total points
A2: Soumya (Member 1) | B2: =COUNTIFS(Backlog!$I$2:$I$40,$A2,Backlog!$H$2:$H$40,"Sprint 1") | C2: =SUMIFS(Backlog!$G$2:$G$40,Backlog!$I$2:$I$40,$A2,Backlog!$H$2:$H$40,"Sprint 1") | D2: =COUNTIFS(Backlog!$I$2:$I$40,$A2,Backlog!$H$2:$H$40,"Sprint 2") | E2: =SUMIFS(Backlog!$G$2:$G$40,Backlog!$I$2:$I$40,$A2,Backlog!$H$2:$H$40,"Sprint 2") | F2: =B2+D2 | G2: =C2+E2
A3: Varnika (Member 2) | B3: =COUNTIFS(Backlog!$I$2:$I$40,$A3,Backlog!$H$2:$H$40,"Sprint 1") | C3: =SUMIFS(Backlog!$G$2:$G$40,Backlog!$I$2:$I$40,$A3,Backlog!$H$2:$H$40,"Sprint 1") | D3: =COUNTIFS(Backlog!$I$2:$I$40,$A3,Backlog!$H$2:$H$40,"Sprint 2") | E3: =SUMIFS(Backlog!$G$2:$G$40,Backlog!$I$2:$I$40,$A3,Backlog!$H$2:$H$40,"Sprint 2") | F3: =B3+D3 | G3: =C3+E3
A4: Tejas (Member 3) | B4: =COUNTIFS(Backlog!$I$2:$I$40,$A4,Backlog!$H$2:$H$40,"Sprint 1") | C4: =SUMIFS(Backlog!$G$2:$G$40,Backlog!$I$2:$I$40,$A4,Backlog!$H$2:$H$40,"Sprint 1") | D4: =COUNTIFS(Backlog!$I$2:$I$40,$A4,Backlog!$H$2:$H$40,"Sprint 2") | E4: =SUMIFS(Backlog!$G$2:$G$40,Backlog!$I$2:$I$40,$A4,Backlog!$H$2:$H$40,"Sprint 2") | F4: =B4+D4 | G4: =C4+E4
A5: Vikas (Member 4) | B5: =COUNTIFS(Backlog!$I$2:$I$40,$A5,Backlog!$H$2:$H$40,"Sprint 1") | C5: =SUMIFS(Backlog!$G$2:$G$40,Backlog!$I$2:$I$40,$A5,Backlog!$H$2:$H$40,"Sprint 1") | D5: =COUNTIFS(Backlog!$I$2:$I$40,$A5,Backlog!$H$2:$H$40,"Sprint 2") | E5: =SUMIFS(Backlog!$G$2:$G$40,Backlog!$I$2:$I$40,$A5,Backlog!$H$2:$H$40,"Sprint 2") | F5: =B5+D5 | G5: =C5+E5
A6: Total | B6: =SUM(B2:B5) | C6: =SUM(C2:C5) | D6: =SUM(D2:D5) | E6: =SUM(E2:E5) | F6: =SUM(F2:F5) | G6: =SUM(G2:G5)
A8: Minimum stories per sprint (from class) | B8: 15
A9: Sprint 1 meets the minimum? | B9: =IF(B6>=$B$8,"Yes","No")
A10: Sprint 2 meets the minimum? | B10: =IF(D6>=$B$8,"Yes","No")
A11: Assumption: 15 stories per sprint is the minimum the professor stated in class (13 Oct 2026).

Sheet Owner changes
A1: Story ID | B1: Old ID | C1: Story | D1: Was | E1: Now | F1: GitHub username (new owner)
A2: US-09 | B2: US-16 | C2: Safe model artifacts | D2: Varnika (Member 2) | E2: Tejas (Member 3) | F2: TejasPonnappa
A3: US-14 | B3: US-38 | C3: Django project skeleton | D3: Tejas (Member 3) | E3: Soumya (Member 1) | F3: KOTRASAISOUMYASRI
A4: US-16 | B4: US-40 | C4: Password hashing | D4: Tejas (Member 3) | E4: Soumya (Member 1) | F4: KOTRASAISOUMYASRI
A5: US-18 | B5: US-42 | C5: Sessions and login protection | D5: Tejas (Member 3) | E5: Soumya (Member 1) | F5: KOTRASAISOUMYASRI
A6: US-29 | B6: US-28 | C6: Security validation | D6: Varnika (Member 2) | E6: Soumya (Member 1) | F6: KOTRASAISOUMYASRI
A7: US-31 | B7: US-30 | C7: Usability test | D7: Varnika (Member 2) | E7: Tejas (Member 3) | F7: TejasPonnappa
A8: US-39 | B8: US-45 | C8: Request and job limits | D8: Tejas (Member 3) | E8: Varnika (Member 2) | F8: varnikasadineni

Sheet Removed
A1: Old story ID | B1: Story | C1: Reason
A2: US-06 | B2: Record design deviations | C2: Deviations are recorded in the final report and deviation log story; epic Architecture & Software Design (old WBMME-3) removed with it
A3: US-01 | B3: Repository, organisation and access | C3: Done at the 13 Oct checkpoint; no product value
A4: US-02 | B4: Backlog and sprint plan | C4: Done; the backlog itself is the deliverable
A5: US-03 | B5: Final SRS | C5: Document already complete and merged
A6: US-04 | B6: Keep the traceability matrix current | C6: Housekeeping; the RTM lives in the SRS, SAD and Test Plan
A7: US-05 | B7: Final SAD | C7: Document already complete and merged
A9: Kept although not code (required by the Part-2 guidelines): US-29 and US-30 demo videos (old US-35, US-36) and US-31 final report and deviation log (old US-37). Epics removed: old WBMME-1, WBMME-2 and WBMME-3. The removed stories are closed on GitHub with the prefix [Removed].
